mplus_output/uni-23-LASI Pilot_W1.out
Mplus VERSION 8.1 (Mac)
MUTHEN & MUTHEN
04/23/2020  10:56 PM

INPUT INSTRUCTIONS

  DATA:
  FILE = "uni-23-LASI Pilot_W1.dat";

  VARIABLE:
  NAMES = mplusid UDAT UDAY UMON UYER UIWR UDWR UANI UNM5 URE2 URE5 USUB;
   MISSING=.;
   CATEGORICAL ARE all; idvariable = mplusid;
  ANALYSIS:
  estimator = wlsmv; coverage=0;
  MODEL:
  g by UDAT * ;
   g by UDAY * ;
   g by UMON * ;
   g by UYER * ;
   g by UIWR * ;
   g by UDWR * ;
   g by USUB * ;
   g by UNM5 * ;
   g by URE5 * ;
   g by UANI * ;
   g by URE2 * ;
   g @ 1;

  OUTPUT:
  standardized; svalues;



*** WARNING
  Data set contains cases with missing on all variables.
  These cases were not included in the analysis.
  Number of cases with missing on all variables:  64
   1 WARNING(S) FOUND IN THE INPUT INSTRUCTIONS




SUMMARY OF ANALYSIS

Number of groups                                                 1
Number of observations                                        1619

Number of dependent variables                                   11
Number of independent variables                                  0
Number of continuous latent variables                            1

Observed dependent variables

  Binary and ordered categorical (ordinal)
   UDAT        UDAY        UMON        UYER        UIWR        UDWR
   UANI        UNM5        URE2        URE5        USUB

Continuous latent variables
   G

Variables with special functions

  ID variable           MPLUSID

Estimator                                                    WLSMV
Maximum number of iterations                                  1000
Convergence criterion                                    0.500D-04
Maximum number of steepest descent iterations                   20
Maximum number of iterations for H1                           2000
Convergence criterion for H1                             0.100D-03
Parameterization                                             DELTA
Link                                                        PROBIT

Input data file(s)
  uni-23-LASI Pilot_W1.dat

Input data format  FREE


SUMMARY OF DATA

     Number of missing data patterns            22


COVARIANCE COVERAGE OF DATA

Minimum covariance coverage value   0.000


     PROPORTION OF DATA PRESENT


           Covariance Coverage
              UDAT          UDAY          UMON          UYER          UIWR
              ________      ________      ________      ________      ________
 UDAT           0.959
 UDAY           0.956         0.988
 UMON           0.959         0.956         0.959
 UYER           0.959         0.956         0.959         0.959
 UIWR           0.954         0.983         0.954         0.954         0.994
 UDWR           0.952         0.981         0.952         0.952         0.991
 UANI           0.959         0.988         0.959         0.959         0.994
 UNM5           0.954         0.986         0.954         0.954         0.981
 URE2           0.946         0.949         0.946         0.946         0.949
 URE5           0.946         0.949         0.946         0.946         0.949
 USUB           0.513         0.514         0.513         0.513         0.514


           Covariance Coverage
              UDWR          UANI          UNM5          URE2          URE5
              ________      ________      ________      ________      ________
 UDWR           0.993
 UANI           0.993         1.000
 UNM5           0.980         0.986         0.986
 URE2           0.949         0.952         0.947         0.952
 URE5           0.949         0.952         0.947         0.952         0.952
 USUB           0.514         0.515         0.514         0.512         0.512


           Covariance Coverage
              USUB
              ________
 USUB           0.515


UNIVARIATE PROPORTIONS AND COUNTS FOR CATEGORICAL VARIABLES

    UDAT
      Category 1    0.354          550.000
      Category 2    0.646         1002.000
    UDAY
      Category 1    0.118          189.000
      Category 2    0.882         1410.000
    UMON
      Category 1    0.340          528.000
      Category 2    0.660         1024.000
    UYER
      Category 1    0.385          597.000
      Category 2    0.615          955.000
    UIWR
      Category 1    0.019           30.000
      Category 2    0.014           22.000
      Category 3    0.045           72.000
      Category 4    0.101          163.000
      Category 5    0.179          288.000
      Category 6    0.442          711.000
      Category 7    0.111          179.000
      Category 8    0.062          100.000
      Category 9    0.016           26.000
      Category 10    0.012           19.000
    UDWR
      Category 1    0.067          107.000
      Category 2    0.057           92.000
      Category 3    0.127          205.000
      Category 4    0.193          310.000
      Category 5    0.195          313.000
      Category 6    0.264          425.000
      Category 7    0.051           82.000
      Category 8    0.036           58.000
      Category 9    0.007           12.000
      Category 10    0.002            4.000
    UANI
      Category 1    0.406          658.000
      Category 2    0.571          924.000
      Category 3    0.012           19.000
      Category 4    0.011           18.000
    UNM5
      Category 1    0.535          855.000
      Category 2    0.465          742.000
    URE2
      Category 1    0.196          303.000
      Category 2    0.804         1239.000
    URE5
      Category 1    0.353          544.000
      Category 2    0.647          998.000
    USUB
      Category 1    0.031           26.000
      Category 2    0.148          123.000
      Category 3    0.107           89.000
      Category 4    0.136          113.000
      Category 5    0.154          128.000
      Category 6    0.425          354.000



THE MODEL ESTIMATION TERMINATED NORMALLY



MODEL FIT INFORMATION

Number of Free Parameters                       44

Chi-Square Test of Model Fit

          Value                           1503.974*
          Degrees of Freedom                    44
          P-Value                           0.0000

*   The chi-square value for MLM, MLMV, MLR, ULSMV, WLSM and WLSMV cannot be used
    for chi-square difference testing in the regular way.  MLM, MLR and WLSM
    chi-square difference testing is described on the Mplus website.  MLMV, WLSMV,
    and ULSMV difference testing is done using the DIFFTEST option.

RMSEA (Root Mean Square Error Of Approximation)

          Estimate                           0.143
          90 Percent C.I.                    0.137  0.149
          Probability RMSEA <= .05           0.000

CFI/TLI

          CFI                                0.913
          TLI                                0.892

Chi-Square Test of Model Fit for the Baseline Model

          Value                          16930.897
          Degrees of Freedom                    55
          P-Value                           0.0000

SRMR (Standardized Root Mean Square Residual)

          Value                              0.090

Optimum Function Value for Weighted Least-Squares Estimator

          Value                     0.39822978D+00



MODEL RESULTS

                                                    Two-Tailed
                    Estimate       S.E.  Est./S.E.    P-Value

 G        BY
    UDAT               0.848      0.013     64.223      0.000
    UDAY               0.670      0.027     24.878      0.000
    UMON               0.916      0.010     91.525      0.000
    UYER               0.933      0.009     98.873      0.000
    UIWR               0.641      0.017     37.474      0.000
    UDWR               0.546      0.019     29.210      0.000
    USUB               0.321      0.030     10.642      0.000
    UNM5               0.810      0.016     51.416      0.000
    URE5               0.823      0.016     51.305      0.000
    UANI               0.428      0.023     18.748      0.000
    URE2               0.833      0.017     49.395      0.000

 Thresholds
